# -*- coding: utf-8 -*-
#Для работы с исключениями используется конструкция try/except:

try:
    2/0
except ZeroDivisionError:
    print("You can't divide by zero")

#Конструкция try работает таким образом:

#сначала выполняются выражения, которые записаны в блоке try
#если при выполнения блока try не возникло никаких исключений, блок except пропускается, и выполняется дальнейший код
#если во время выполнения блока try в каком-то месте возникло исключение, оставшаяся часть блока try пропускается
#если в блоке except указано исключение, которое возникло, выполняется код в блоке except
#если исключение, которое возникло, не указано в блоке except, выполнение программы прерывается и выдается ошибка

try:
    a = input("Введите первое число: ")
    b = input("Введите второе число: ")
    print("Результат: ", int(a)/int(b))
except ValueError:
    print("Пожалуйста, вводите только числа")
except ZeroDivisionError:
    print("На ноль делить нельзя")

#В конструкции try/except есть опциональный блок else. Он выполняется в том случае, если не было исключения.
try:
    a = input("Введите первое число: ")
    b = input("Введите второе число: ")
    result = int(a)/int(b)
except (ValueError, ZeroDivisionError):
    print("Что-то пошло не так...")
else:
    print("Результат в квадрате: ", result**2)

#Блок finally - это еще один опциональный блок в конструкции try. Он выполняется всегда, независимо от того, было ли исключение или нет.
try:
    a = input("Введите первое число: ")
    b = input("Введите второе число: ")
    result = int(a)/int(b)
except (ValueError, ZeroDivisionError):
    print("Что-то пошло не так...")
else:
    print("Результат в квадрате: ", result**2)
finally:
    print("Вот и сказочке конец, а кто слушал - молодец.")
